2023-06-11 23:24:35,156 ERROR: Exception on /api/reservations/1 [GET] [in C:\Users\Glutt\miniconda3\envs\reserve\Lib\site-packages\flask\app.py:1744]
Traceback (most recent call last):
  File "C:\Users\Glutt\miniconda3\envs\reserve\Lib\site-packages\flask\app.py", line 2528, in wsgi_app
    response = self.full_dispatch_request()
               ^^^^^^^^^^^^^^^^^^^^^^^^^^^^
  File "C:\Users\Glutt\miniconda3\envs\reserve\Lib\site-packages\flask\app.py", line 1825, in full_dispatch_request
    rv = self.handle_user_exception(e)
         ^^^^^^^^^^^^^^^^^^^^^^^^^^^^^
  File "C:\Users\Glutt\miniconda3\envs\reserve\Lib\site-packages\flask_cors\extension.py", line 165, in wrapped_function
    return cors_after_request(app.make_response(f(*args, **kwargs)))
                                                ^^^^^^^^^^^^^^^^^^
  File "C:\Users\Glutt\miniconda3\envs\reserve\Lib\site-packages\flask\app.py", line 1823, in full_dispatch_request
    rv = self.dispatch_request()
         ^^^^^^^^^^^^^^^^^^^^^^^
  File "C:\Users\Glutt\miniconda3\envs\reserve\Lib\site-packages\flask\app.py", line 1799, in dispatch_request
    return self.ensure_sync(self.view_functions[rule.endpoint])(**view_args)
           ^^^^^^^^^^^^^^^^^^^^^^^^^^^^^^^^^^^^^^^^^^^^^^^^^^^^^^^^^^^^^^^^^
  File "C:\Users\Glutt\reservation_system\backend\app\routes.py", line 601, in get_reservation_user_id
    def get_reservation_user_id(user_id:int)-> Tuple[Response, int]:
                      ^^^^^^^^^^^^^^^^^^^^^^^^^^^^^^^^^^^^^^^^^^^^^^^
TypeError: ReservationService.get_reservations_by_user_id() takes 1 positional argument but 2 were given
2023-06-11 23:24:43,036 ERROR: Exception on /api/reservations/1 [GET] [in C:\Users\Glutt\miniconda3\envs\reserve\Lib\site-packages\flask\app.py:1744]
Traceback (most recent call last):
  File "C:\Users\Glutt\miniconda3\envs\reserve\Lib\site-packages\flask\app.py", line 2528, in wsgi_app
    response = self.full_dispatch_request()
               ^^^^^^^^^^^^^^^^^^^^^^^^^^^^
  File "C:\Users\Glutt\miniconda3\envs\reserve\Lib\site-packages\flask\app.py", line 1825, in full_dispatch_request
    rv = self.handle_user_exception(e)
         ^^^^^^^^^^^^^^^^^^^^^^^^^^^^^
  File "C:\Users\Glutt\miniconda3\envs\reserve\Lib\site-packages\flask_cors\extension.py", line 165, in wrapped_function
    return cors_after_request(app.make_response(f(*args, **kwargs)))
                                                ^^^^^^^^^^^^^^^^^^
  File "C:\Users\Glutt\miniconda3\envs\reserve\Lib\site-packages\flask\app.py", line 1823, in full_dispatch_request
    rv = self.dispatch_request()
         ^^^^^^^^^^^^^^^^^^^^^^^
  File "C:\Users\Glutt\miniconda3\envs\reserve\Lib\site-packages\flask\app.py", line 1799, in dispatch_request
    return self.ensure_sync(self.view_functions[rule.endpoint])(**view_args)
           ^^^^^^^^^^^^^^^^^^^^^^^^^^^^^^^^^^^^^^^^^^^^^^^^^^^^^^^^^^^^^^^^^
  File "C:\Users\Glutt\reservation_system\backend\app\routes.py", line 601, in get_reservation_user_id
    def get_reservation_user_id(user_id:int)-> Tuple[Response, int]:
                      ^^^^^^^^^^^^^^^^^^^^^^^^^^^^^^^^^^^^^^^^^^^^^^^
TypeError: ReservationService.get_reservations_by_user_id() takes 1 positional argument but 2 were given
2023-06-11 23:24:56,775 INFO: MyApp startup [in C:\Users\Glutt\reservation_system\backend\app\__init__.py:27]
2023-06-11 23:25:00,559 ERROR: Exception on /api/reservations/1 [GET] [in C:\Users\Glutt\miniconda3\envs\reserve\Lib\site-packages\flask\app.py:1744]
Traceback (most recent call last):
  File "C:\Users\Glutt\miniconda3\envs\reserve\Lib\site-packages\flask\app.py", line 2528, in wsgi_app
    response = self.full_dispatch_request()
               ^^^^^^^^^^^^^^^^^^^^^^^^^^^^
  File "C:\Users\Glutt\miniconda3\envs\reserve\Lib\site-packages\flask\app.py", line 1825, in full_dispatch_request
    rv = self.handle_user_exception(e)
         ^^^^^^^^^^^^^^^^^^^^^^^^^^^^^
  File "C:\Users\Glutt\miniconda3\envs\reserve\Lib\site-packages\flask_cors\extension.py", line 165, in wrapped_function
    return cors_after_request(app.make_response(f(*args, **kwargs)))
                                                ^^^^^^^^^^^^^^^^^^
  File "C:\Users\Glutt\miniconda3\envs\reserve\Lib\site-packages\flask\app.py", line 1823, in full_dispatch_request
    rv = self.dispatch_request()
         ^^^^^^^^^^^^^^^^^^^^^^^
  File "C:\Users\Glutt\miniconda3\envs\reserve\Lib\site-packages\flask\app.py", line 1799, in dispatch_request
    return self.ensure_sync(self.view_functions[rule.endpoint])(**view_args)
           ^^^^^^^^^^^^^^^^^^^^^^^^^^^^^^^^^^^^^^^^^^^^^^^^^^^^^^^^^^^^^^^^^
  File "C:\Users\Glutt\reservation_system\backend\app\routes.py", line 603, in get_reservation_user_id
    return jsonify(reservation.to_dict()),200
                   ^^^^^^^^^^^^^^^^^^^
AttributeError: 'list' object has no attribute 'to_dict'
2023-06-11 23:25:00,808 ERROR: Exception on /api/reservations/1 [GET] [in C:\Users\Glutt\miniconda3\envs\reserve\Lib\site-packages\flask\app.py:1744]
Traceback (most recent call last):
  File "C:\Users\Glutt\miniconda3\envs\reserve\Lib\site-packages\flask\app.py", line 2528, in wsgi_app
    response = self.full_dispatch_request()
               ^^^^^^^^^^^^^^^^^^^^^^^^^^^^
  File "C:\Users\Glutt\miniconda3\envs\reserve\Lib\site-packages\flask\app.py", line 1825, in full_dispatch_request
    rv = self.handle_user_exception(e)
         ^^^^^^^^^^^^^^^^^^^^^^^^^^^^^
  File "C:\Users\Glutt\miniconda3\envs\reserve\Lib\site-packages\flask_cors\extension.py", line 165, in wrapped_function
    return cors_after_request(app.make_response(f(*args, **kwargs)))
                                                ^^^^^^^^^^^^^^^^^^
  File "C:\Users\Glutt\miniconda3\envs\reserve\Lib\site-packages\flask\app.py", line 1823, in full_dispatch_request
    rv = self.dispatch_request()
         ^^^^^^^^^^^^^^^^^^^^^^^
  File "C:\Users\Glutt\miniconda3\envs\reserve\Lib\site-packages\flask\app.py", line 1799, in dispatch_request
    return self.ensure_sync(self.view_functions[rule.endpoint])(**view_args)
           ^^^^^^^^^^^^^^^^^^^^^^^^^^^^^^^^^^^^^^^^^^^^^^^^^^^^^^^^^^^^^^^^^
  File "C:\Users\Glutt\reservation_system\backend\app\routes.py", line 603, in get_reservation_user_id
    return jsonify(reservation.to_dict()),200
                   ^^^^^^^^^^^^^^^^^^^
AttributeError: 'list' object has no attribute 'to_dict'
2023-06-11 23:25:37,431 INFO: MyApp startup [in C:\Users\Glutt\reservation_system\backend\app\__init__.py:27]
2023-06-11 23:25:41,282 ERROR: Exception on /api/reservations/1 [GET] [in C:\Users\Glutt\miniconda3\envs\reserve\Lib\site-packages\flask\app.py:1744]
Traceback (most recent call last):
  File "C:\Users\Glutt\miniconda3\envs\reserve\Lib\site-packages\flask\app.py", line 2528, in wsgi_app
    response = self.full_dispatch_request()
               ^^^^^^^^^^^^^^^^^^^^^^^^^^^^
  File "C:\Users\Glutt\miniconda3\envs\reserve\Lib\site-packages\flask\app.py", line 1825, in full_dispatch_request
    rv = self.handle_user_exception(e)
         ^^^^^^^^^^^^^^^^^^^^^^^^^^^^^
  File "C:\Users\Glutt\miniconda3\envs\reserve\Lib\site-packages\flask_cors\extension.py", line 165, in wrapped_function
    return cors_after_request(app.make_response(f(*args, **kwargs)))
                                                ^^^^^^^^^^^^^^^^^^
  File "C:\Users\Glutt\miniconda3\envs\reserve\Lib\site-packages\flask\app.py", line 1823, in full_dispatch_request
    rv = self.dispatch_request()
         ^^^^^^^^^^^^^^^^^^^^^^^
  File "C:\Users\Glutt\miniconda3\envs\reserve\Lib\site-packages\flask\app.py", line 1799, in dispatch_request
    return self.ensure_sync(self.view_functions[rule.endpoint])(**view_args)
           ^^^^^^^^^^^^^^^^^^^^^^^^^^^^^^^^^^^^^^^^^^^^^^^^^^^^^^^^^^^^^^^^^
  File "C:\Users\Glutt\reservation_system\backend\app\routes.py", line 603, in get_reservation_user_id
    return jsonify(reservation.to_dict()),200
                   ^^^^^^^^^^^^^^^^^^^
AttributeError: 'list' object has no attribute 'to_dict'
2023-06-11 23:25:41,528 ERROR: Exception on /api/reservations/1 [GET] [in C:\Users\Glutt\miniconda3\envs\reserve\Lib\site-packages\flask\app.py:1744]
Traceback (most recent call last):
  File "C:\Users\Glutt\miniconda3\envs\reserve\Lib\site-packages\flask\app.py", line 2528, in wsgi_app
    response = self.full_dispatch_request()
               ^^^^^^^^^^^^^^^^^^^^^^^^^^^^
  File "C:\Users\Glutt\miniconda3\envs\reserve\Lib\site-packages\flask\app.py", line 1825, in full_dispatch_request
    rv = self.handle_user_exception(e)
         ^^^^^^^^^^^^^^^^^^^^^^^^^^^^^
  File "C:\Users\Glutt\miniconda3\envs\reserve\Lib\site-packages\flask_cors\extension.py", line 165, in wrapped_function
    return cors_after_request(app.make_response(f(*args, **kwargs)))
                                                ^^^^^^^^^^^^^^^^^^
  File "C:\Users\Glutt\miniconda3\envs\reserve\Lib\site-packages\flask\app.py", line 1823, in full_dispatch_request
    rv = self.dispatch_request()
         ^^^^^^^^^^^^^^^^^^^^^^^
  File "C:\Users\Glutt\miniconda3\envs\reserve\Lib\site-packages\flask\app.py", line 1799, in dispatch_request
    return self.ensure_sync(self.view_functions[rule.endpoint])(**view_args)
           ^^^^^^^^^^^^^^^^^^^^^^^^^^^^^^^^^^^^^^^^^^^^^^^^^^^^^^^^^^^^^^^^^
  File "C:\Users\Glutt\reservation_system\backend\app\routes.py", line 603, in get_reservation_user_id
    return jsonify(reservation.to_dict()),200
                   ^^^^^^^^^^^^^^^^^^^
AttributeError: 'list' object has no attribute 'to_dict'
