2023-06-11 22:10:19,303 ERROR: Exception on /api/reservations/1 [GET] [in C:\Users\Glutt\miniconda3\envs\reserve\Lib\site-packages\flask\app.py:1744]
Traceback (most recent call last):
  File "C:\Users\Glutt\miniconda3\envs\reserve\Lib\site-packages\flask\app.py", line 2528, in wsgi_app
    response = self.full_dispatch_request()
               ^^^^^^^^^^^^^^^^^^^^^^^^^^^^
  File "C:\Users\Glutt\miniconda3\envs\reserve\Lib\site-packages\flask\app.py", line 1825, in full_dispatch_request
    rv = self.handle_user_exception(e)
         ^^^^^^^^^^^^^^^^^^^^^^^^^^^^^
  File "C:\Users\Glutt\miniconda3\envs\reserve\Lib\site-packages\flask_cors\extension.py", line 165, in wrapped_function
    return cors_after_request(app.make_response(f(*args, **kwargs)))
                                                ^^^^^^^^^^^^^^^^^^
  File "C:\Users\Glutt\miniconda3\envs\reserve\Lib\site-packages\flask\app.py", line 1823, in full_dispatch_request
    rv = self.dispatch_request()
         ^^^^^^^^^^^^^^^^^^^^^^^
  File "C:\Users\Glutt\miniconda3\envs\reserve\Lib\site-packages\flask\app.py", line 1799, in dispatch_request
    return self.ensure_sync(self.view_functions[rule.endpoint])(**view_args)
           ^^^^^^^^^^^^^^^^^^^^^^^^^^^^^^^^^^^^^^^^^^^^^^^^^^^^^^^^^^^^^^^^^
TypeError: get_reservation() got an unexpected keyword argument 'id'
2023-06-11 22:10:21,956 ERROR: Exception on /api/reservations/1 [GET] [in C:\Users\Glutt\miniconda3\envs\reserve\Lib\site-packages\flask\app.py:1744]
Traceback (most recent call last):
  File "C:\Users\Glutt\miniconda3\envs\reserve\Lib\site-packages\flask\app.py", line 2528, in wsgi_app
    response = self.full_dispatch_request()
               ^^^^^^^^^^^^^^^^^^^^^^^^^^^^
  File "C:\Users\Glutt\miniconda3\envs\reserve\Lib\site-packages\flask\app.py", line 1825, in full_dispatch_request
    rv = self.handle_user_exception(e)
         ^^^^^^^^^^^^^^^^^^^^^^^^^^^^^
  File "C:\Users\Glutt\miniconda3\envs\reserve\Lib\site-packages\flask_cors\extension.py", line 165, in wrapped_function
    return cors_after_request(app.make_response(f(*args, **kwargs)))
                                                ^^^^^^^^^^^^^^^^^^
  File "C:\Users\Glutt\miniconda3\envs\reserve\Lib\site-packages\flask\app.py", line 1823, in full_dispatch_request
    rv = self.dispatch_request()
         ^^^^^^^^^^^^^^^^^^^^^^^
  File "C:\Users\Glutt\miniconda3\envs\reserve\Lib\site-packages\flask\app.py", line 1799, in dispatch_request
    return self.ensure_sync(self.view_functions[rule.endpoint])(**view_args)
           ^^^^^^^^^^^^^^^^^^^^^^^^^^^^^^^^^^^^^^^^^^^^^^^^^^^^^^^^^^^^^^^^^
TypeError: get_reservation() got an unexpected keyword argument 'id'
2023-06-11 22:10:22,262 ERROR: Exception on /api/reservations/1 [GET] [in C:\Users\Glutt\miniconda3\envs\reserve\Lib\site-packages\flask\app.py:1744]
Traceback (most recent call last):
  File "C:\Users\Glutt\miniconda3\envs\reserve\Lib\site-packages\flask\app.py", line 2528, in wsgi_app
    response = self.full_dispatch_request()
               ^^^^^^^^^^^^^^^^^^^^^^^^^^^^
  File "C:\Users\Glutt\miniconda3\envs\reserve\Lib\site-packages\flask\app.py", line 1825, in full_dispatch_request
    rv = self.handle_user_exception(e)
         ^^^^^^^^^^^^^^^^^^^^^^^^^^^^^
  File "C:\Users\Glutt\miniconda3\envs\reserve\Lib\site-packages\flask_cors\extension.py", line 165, in wrapped_function
    return cors_after_request(app.make_response(f(*args, **kwargs)))
                                                ^^^^^^^^^^^^^^^^^^
  File "C:\Users\Glutt\miniconda3\envs\reserve\Lib\site-packages\flask\app.py", line 1823, in full_dispatch_request
    rv = self.dispatch_request()
         ^^^^^^^^^^^^^^^^^^^^^^^
  File "C:\Users\Glutt\miniconda3\envs\reserve\Lib\site-packages\flask\app.py", line 1799, in dispatch_request
    return self.ensure_sync(self.view_functions[rule.endpoint])(**view_args)
           ^^^^^^^^^^^^^^^^^^^^^^^^^^^^^^^^^^^^^^^^^^^^^^^^^^^^^^^^^^^^^^^^^
TypeError: get_reservation() got an unexpected keyword argument 'id'
2023-06-11 22:10:28,178 INFO: MyApp startup [in C:\Users\Glutt\reservation_system\backend\app\__init__.py:27]
2023-06-11 22:13:48,669 INFO: MyApp startup [in C:\Users\Glutt\reservation_system\backend\app\__init__.py:27]
2023-06-11 22:17:26,177 INFO: MyApp startup [in C:\Users\Glutt\reservation_system\backend\app\__init__.py:27]
2023-06-11 22:37:06,002 INFO: MyApp startup [in C:\Users\Glutt\reservation_system\backend\app\__init__.py:27]
2023-06-11 22:53:43,594 INFO: MyApp startup [in C:\Users\Glutt\reservation_system\backend\app\__init__.py:27]
2023-06-11 22:55:51,125 INFO: MyApp startup [in C:\Users\Glutt\reservation_system\backend\app\__init__.py:27]
2023-06-11 23:11:24,074 INFO: MyApp startup [in C:\Users\Glutt\reservation_system\backend\app\__init__.py:27]
2023-06-11 23:11:30,885 ERROR: Exception on /api/reservations/1 [GET] [in C:\Users\Glutt\miniconda3\envs\reserve\Lib\site-packages\flask\app.py:1744]
Traceback (most recent call last):
  File "C:\Users\Glutt\miniconda3\envs\reserve\Lib\site-packages\flask\app.py", line 2528, in wsgi_app
    response = self.full_dispatch_request()
               ^^^^^^^^^^^^^^^^^^^^^^^^^^^^
  File "C:\Users\Glutt\miniconda3\envs\reserve\Lib\site-packages\flask\app.py", line 1825, in full_dispatch_request
    rv = self.handle_user_exception(e)
         ^^^^^^^^^^^^^^^^^^^^^^^^^^^^^
  File "C:\Users\Glutt\miniconda3\envs\reserve\Lib\site-packages\flask_cors\extension.py", line 165, in wrapped_function
    return cors_after_request(app.make_response(f(*args, **kwargs)))
                                                ^^^^^^^^^^^^^^^^^^
  File "C:\Users\Glutt\miniconda3\envs\reserve\Lib\site-packages\flask\app.py", line 1823, in full_dispatch_request
    rv = self.dispatch_request()
         ^^^^^^^^^^^^^^^^^^^^^^^
  File "C:\Users\Glutt\miniconda3\envs\reserve\Lib\site-packages\flask\app.py", line 1799, in dispatch_request
    return self.ensure_sync(self.view_functions[rule.endpoint])(**view_args)
           ^^^^^^^^^^^^^^^^^^^^^^^^^^^^^^^^^^^^^^^^^^^^^^^^^^^^^^^^^^^^^^^^^
  File "C:\Users\Glutt\reservation_system\backend\app\routes.py", line 601, in get_reservation_user_id
    reservation = ReservationService.get_reservations_by_user_id(user_id)
                  ^^^^^^^^^^^^^^^^^^^^^^^^^^^^^^^^^^^^^^^^^^^^^^^^^^^^^^^
TypeError: ReservationService.get_reservations_by_user_id() takes 1 positional argument but 2 were given
2023-06-11 23:11:31,141 ERROR: Exception on /api/reservations/1 [GET] [in C:\Users\Glutt\miniconda3\envs\reserve\Lib\site-packages\flask\app.py:1744]
Traceback (most recent call last):
  File "C:\Users\Glutt\miniconda3\envs\reserve\Lib\site-packages\flask\app.py", line 2528, in wsgi_app
    response = self.full_dispatch_request()
               ^^^^^^^^^^^^^^^^^^^^^^^^^^^^
  File "C:\Users\Glutt\miniconda3\envs\reserve\Lib\site-packages\flask\app.py", line 1825, in full_dispatch_request
    rv = self.handle_user_exception(e)
         ^^^^^^^^^^^^^^^^^^^^^^^^^^^^^
  File "C:\Users\Glutt\miniconda3\envs\reserve\Lib\site-packages\flask_cors\extension.py", line 165, in wrapped_function
    return cors_after_request(app.make_response(f(*args, **kwargs)))
                                                ^^^^^^^^^^^^^^^^^^
  File "C:\Users\Glutt\miniconda3\envs\reserve\Lib\site-packages\flask\app.py", line 1823, in full_dispatch_request
    rv = self.dispatch_request()
         ^^^^^^^^^^^^^^^^^^^^^^^
  File "C:\Users\Glutt\miniconda3\envs\reserve\Lib\site-packages\flask\app.py", line 1799, in dispatch_request
    return self.ensure_sync(self.view_functions[rule.endpoint])(**view_args)
           ^^^^^^^^^^^^^^^^^^^^^^^^^^^^^^^^^^^^^^^^^^^^^^^^^^^^^^^^^^^^^^^^^
  File "C:\Users\Glutt\reservation_system\backend\app\routes.py", line 601, in get_reservation_user_id
    reservation = ReservationService.get_reservations_by_user_id(user_id)
                  ^^^^^^^^^^^^^^^^^^^^^^^^^^^^^^^^^^^^^^^^^^^^^^^^^^^^^^^
TypeError: ReservationService.get_reservations_by_user_id() takes 1 positional argument but 2 were given
2023-06-11 23:15:00,017 ERROR: Exception on /api/reservations/1 [GET] [in C:\Users\Glutt\miniconda3\envs\reserve\Lib\site-packages\flask\app.py:1744]
Traceback (most recent call last):
  File "C:\Users\Glutt\miniconda3\envs\reserve\Lib\site-packages\flask\app.py", line 2528, in wsgi_app
    response = self.full_dispatch_request()
               ^^^^^^^^^^^^^^^^^^^^^^^^^^^^
  File "C:\Users\Glutt\miniconda3\envs\reserve\Lib\site-packages\flask\app.py", line 1825, in full_dispatch_request
    rv = self.handle_user_exception(e)
         ^^^^^^^^^^^^^^^^^^^^^^^^^^^^^
  File "C:\Users\Glutt\miniconda3\envs\reserve\Lib\site-packages\flask_cors\extension.py", line 165, in wrapped_function
    return cors_after_request(app.make_response(f(*args, **kwargs)))
                                                ^^^^^^^^^^^^^^^^^^
  File "C:\Users\Glutt\miniconda3\envs\reserve\Lib\site-packages\flask\app.py", line 1823, in full_dispatch_request
    rv = self.dispatch_request()
         ^^^^^^^^^^^^^^^^^^^^^^^
  File "C:\Users\Glutt\miniconda3\envs\reserve\Lib\site-packages\flask\app.py", line 1799, in dispatch_request
    return self.ensure_sync(self.view_functions[rule.endpoint])(**view_args)
           ^^^^^^^^^^^^^^^^^^^^^^^^^^^^^^^^^^^^^^^^^^^^^^^^^^^^^^^^^^^^^^^^^
  File "C:\Users\Glutt\reservation_system\backend\app\routes.py", line 601, in get_reservation_user_id
    reservation = ReservationService.get_reservations_by_user_id(user_id)
                  ^^^^^^^^^^^^^^^^^^^^^^^^^^^^^^^^^^^^^^^^^^^^^^^^^^^^^^^
TypeError: ReservationService.get_reservations_by_user_id() takes 1 positional argument but 2 were given
