2023-06-11 23:15:02,163 ERROR: Exception on /api/reservations/1 [GET] [in C:\Users\Glutt\miniconda3\envs\reserve\Lib\site-packages\flask\app.py:1744]
Traceback (most recent call last):
  File "C:\Users\Glutt\miniconda3\envs\reserve\Lib\site-packages\flask\app.py", line 2528, in wsgi_app
    response = self.full_dispatch_request()
               ^^^^^^^^^^^^^^^^^^^^^^^^^^^^
  File "C:\Users\Glutt\miniconda3\envs\reserve\Lib\site-packages\flask\app.py", line 1825, in full_dispatch_request
    rv = self.handle_user_exception(e)
         ^^^^^^^^^^^^^^^^^^^^^^^^^^^^^
  File "C:\Users\Glutt\miniconda3\envs\reserve\Lib\site-packages\flask_cors\extension.py", line 165, in wrapped_function
    return cors_after_request(app.make_response(f(*args, **kwargs)))
                                                ^^^^^^^^^^^^^^^^^^
  File "C:\Users\Glutt\miniconda3\envs\reserve\Lib\site-packages\flask\app.py", line 1823, in full_dispatch_request
    rv = self.dispatch_request()
         ^^^^^^^^^^^^^^^^^^^^^^^
  File "C:\Users\Glutt\miniconda3\envs\reserve\Lib\site-packages\flask\app.py", line 1799, in dispatch_request
    return self.ensure_sync(self.view_functions[rule.endpoint])(**view_args)
           ^^^^^^^^^^^^^^^^^^^^^^^^^^^^^^^^^^^^^^^^^^^^^^^^^^^^^^^^^^^^^^^^^
  File "C:\Users\Glutt\reservation_system\backend\app\routes.py", line 601, in get_reservation_user_id
    reservation = ReservationService.get_reservations_by_user_id(user_id)
                  ^^^^^^^^^^^^^^^^^^^^^^^^^^^^^^^^^^^^^^^^^^^^^^^^^^^^^^^
TypeError: ReservationService.get_reservations_by_user_id() takes 1 positional argument but 2 were given
2023-06-11 23:16:08,821 INFO: MyApp startup [in C:\Users\Glutt\reservation_system\backend\app\__init__.py:27]
2023-06-11 23:16:12,190 ERROR: Exception on /api/reservations/1 [GET] [in C:\Users\Glutt\miniconda3\envs\reserve\Lib\site-packages\flask\app.py:1744]
Traceback (most recent call last):
  File "C:\Users\Glutt\miniconda3\envs\reserve\Lib\site-packages\flask\app.py", line 2528, in wsgi_app
    response = self.full_dispatch_request()
               ^^^^^^^^^^^^^^^^^^^^^^^^^^^^
  File "C:\Users\Glutt\miniconda3\envs\reserve\Lib\site-packages\flask\app.py", line 1825, in full_dispatch_request
    rv = self.handle_user_exception(e)
         ^^^^^^^^^^^^^^^^^^^^^^^^^^^^^
  File "C:\Users\Glutt\miniconda3\envs\reserve\Lib\site-packages\flask_cors\extension.py", line 165, in wrapped_function
    return cors_after_request(app.make_response(f(*args, **kwargs)))
                                                ^^^^^^^^^^^^^^^^^^
  File "C:\Users\Glutt\miniconda3\envs\reserve\Lib\site-packages\flask\app.py", line 1823, in full_dispatch_request
    rv = self.dispatch_request()
         ^^^^^^^^^^^^^^^^^^^^^^^
  File "C:\Users\Glutt\miniconda3\envs\reserve\Lib\site-packages\flask\app.py", line 1799, in dispatch_request
    return self.ensure_sync(self.view_functions[rule.endpoint])(**view_args)
           ^^^^^^^^^^^^^^^^^^^^^^^^^^^^^^^^^^^^^^^^^^^^^^^^^^^^^^^^^^^^^^^^^
  File "C:\Users\Glutt\reservation_system\backend\app\routes.py", line 601, in get_reservation_user_id
    reservation = ReservationService.get_reservations_by_user_id(user_id)
                  ^^^^^^^^^^^^^^^^^^^^^^^^^^^^^^^^^^^^^^^^^^^^^^^^^^^^^^^
TypeError: ReservationService.get_reservations_by_user_id() takes 1 positional argument but 2 were given
2023-06-11 23:16:12,440 ERROR: Exception on /api/reservations/1 [GET] [in C:\Users\Glutt\miniconda3\envs\reserve\Lib\site-packages\flask\app.py:1744]
Traceback (most recent call last):
  File "C:\Users\Glutt\miniconda3\envs\reserve\Lib\site-packages\flask\app.py", line 2528, in wsgi_app
    response = self.full_dispatch_request()
               ^^^^^^^^^^^^^^^^^^^^^^^^^^^^
  File "C:\Users\Glutt\miniconda3\envs\reserve\Lib\site-packages\flask\app.py", line 1825, in full_dispatch_request
    rv = self.handle_user_exception(e)
         ^^^^^^^^^^^^^^^^^^^^^^^^^^^^^
  File "C:\Users\Glutt\miniconda3\envs\reserve\Lib\site-packages\flask_cors\extension.py", line 165, in wrapped_function
    return cors_after_request(app.make_response(f(*args, **kwargs)))
                                                ^^^^^^^^^^^^^^^^^^
  File "C:\Users\Glutt\miniconda3\envs\reserve\Lib\site-packages\flask\app.py", line 1823, in full_dispatch_request
    rv = self.dispatch_request()
         ^^^^^^^^^^^^^^^^^^^^^^^
  File "C:\Users\Glutt\miniconda3\envs\reserve\Lib\site-packages\flask\app.py", line 1799, in dispatch_request
    return self.ensure_sync(self.view_functions[rule.endpoint])(**view_args)
           ^^^^^^^^^^^^^^^^^^^^^^^^^^^^^^^^^^^^^^^^^^^^^^^^^^^^^^^^^^^^^^^^^
  File "C:\Users\Glutt\reservation_system\backend\app\routes.py", line 601, in get_reservation_user_id
    reservation = ReservationService.get_reservations_by_user_id(user_id)
                  ^^^^^^^^^^^^^^^^^^^^^^^^^^^^^^^^^^^^^^^^^^^^^^^^^^^^^^^
TypeError: ReservationService.get_reservations_by_user_id() takes 1 positional argument but 2 were given
2023-06-11 23:20:24,388 ERROR: Exception on /api/reservations/1 [GET] [in C:\Users\Glutt\miniconda3\envs\reserve\Lib\site-packages\flask\app.py:1744]
Traceback (most recent call last):
  File "C:\Users\Glutt\miniconda3\envs\reserve\Lib\site-packages\flask\app.py", line 2528, in wsgi_app
    response = self.full_dispatch_request()
               ^^^^^^^^^^^^^^^^^^^^^^^^^^^^
  File "C:\Users\Glutt\miniconda3\envs\reserve\Lib\site-packages\flask\app.py", line 1825, in full_dispatch_request
    rv = self.handle_user_exception(e)
         ^^^^^^^^^^^^^^^^^^^^^^^^^^^^^
  File "C:\Users\Glutt\miniconda3\envs\reserve\Lib\site-packages\flask_cors\extension.py", line 165, in wrapped_function
    return cors_after_request(app.make_response(f(*args, **kwargs)))
                                                ^^^^^^^^^^^^^^^^^^
  File "C:\Users\Glutt\miniconda3\envs\reserve\Lib\site-packages\flask\app.py", line 1823, in full_dispatch_request
    rv = self.dispatch_request()
         ^^^^^^^^^^^^^^^^^^^^^^^
  File "C:\Users\Glutt\miniconda3\envs\reserve\Lib\site-packages\flask\app.py", line 1799, in dispatch_request
    return self.ensure_sync(self.view_functions[rule.endpoint])(**view_args)
           ^^^^^^^^^^^^^^^^^^^^^^^^^^^^^^^^^^^^^^^^^^^^^^^^^^^^^^^^^^^^^^^^^
  File "C:\Users\Glutt\reservation_system\backend\app\routes.py", line 601, in get_reservation_user_id
    reservation = ReservationService.get_reservations_by_user_id(user_id)
                  ^^^^^^^^^^^^^^^^^^^^^^^^^^^^^^^^^^^^^^^^^^^^^^^^^^^^^^^
TypeError: ReservationService.get_reservations_by_user_id() takes 1 positional argument but 2 were given
2023-06-11 23:20:24,639 ERROR: Exception on /api/reservations/1 [GET] [in C:\Users\Glutt\miniconda3\envs\reserve\Lib\site-packages\flask\app.py:1744]
Traceback (most recent call last):
  File "C:\Users\Glutt\miniconda3\envs\reserve\Lib\site-packages\flask\app.py", line 2528, in wsgi_app
    response = self.full_dispatch_request()
               ^^^^^^^^^^^^^^^^^^^^^^^^^^^^
  File "C:\Users\Glutt\miniconda3\envs\reserve\Lib\site-packages\flask\app.py", line 1825, in full_dispatch_request
    rv = self.handle_user_exception(e)
         ^^^^^^^^^^^^^^^^^^^^^^^^^^^^^
  File "C:\Users\Glutt\miniconda3\envs\reserve\Lib\site-packages\flask_cors\extension.py", line 165, in wrapped_function
    return cors_after_request(app.make_response(f(*args, **kwargs)))
                                                ^^^^^^^^^^^^^^^^^^
  File "C:\Users\Glutt\miniconda3\envs\reserve\Lib\site-packages\flask\app.py", line 1823, in full_dispatch_request
    rv = self.dispatch_request()
         ^^^^^^^^^^^^^^^^^^^^^^^
  File "C:\Users\Glutt\miniconda3\envs\reserve\Lib\site-packages\flask\app.py", line 1799, in dispatch_request
    return self.ensure_sync(self.view_functions[rule.endpoint])(**view_args)
           ^^^^^^^^^^^^^^^^^^^^^^^^^^^^^^^^^^^^^^^^^^^^^^^^^^^^^^^^^^^^^^^^^
  File "C:\Users\Glutt\reservation_system\backend\app\routes.py", line 601, in get_reservation_user_id
    reservation = ReservationService.get_reservations_by_user_id(user_id)
                  ^^^^^^^^^^^^^^^^^^^^^^^^^^^^^^^^^^^^^^^^^^^^^^^^^^^^^^^
TypeError: ReservationService.get_reservations_by_user_id() takes 1 positional argument but 2 were given
2023-06-11 23:24:26,931 ERROR: Exception on /api/reservations/1 [GET] [in C:\Users\Glutt\miniconda3\envs\reserve\Lib\site-packages\flask\app.py:1744]
Traceback (most recent call last):
  File "C:\Users\Glutt\miniconda3\envs\reserve\Lib\site-packages\flask\app.py", line 2528, in wsgi_app
    response = self.full_dispatch_request()
               ^^^^^^^^^^^^^^^^^^^^^^^^^^^^
  File "C:\Users\Glutt\miniconda3\envs\reserve\Lib\site-packages\flask\app.py", line 1825, in full_dispatch_request
    rv = self.handle_user_exception(e)
         ^^^^^^^^^^^^^^^^^^^^^^^^^^^^^
  File "C:\Users\Glutt\miniconda3\envs\reserve\Lib\site-packages\flask_cors\extension.py", line 165, in wrapped_function
    return cors_after_request(app.make_response(f(*args, **kwargs)))
                                                ^^^^^^^^^^^^^^^^^^
  File "C:\Users\Glutt\miniconda3\envs\reserve\Lib\site-packages\flask\app.py", line 1823, in full_dispatch_request
    rv = self.dispatch_request()
         ^^^^^^^^^^^^^^^^^^^^^^^
  File "C:\Users\Glutt\miniconda3\envs\reserve\Lib\site-packages\flask\app.py", line 1799, in dispatch_request
    return self.ensure_sync(self.view_functions[rule.endpoint])(**view_args)
           ^^^^^^^^^^^^^^^^^^^^^^^^^^^^^^^^^^^^^^^^^^^^^^^^^^^^^^^^^^^^^^^^^
  File "C:\Users\Glutt\reservation_system\backend\app\routes.py", line 601, in get_reservation_user_id
    def get_reservation_user_id(user_id:int)-> Tuple[Response, int]:
                      ^^^^^^^^^^^^^^^^^^^^^^^^^^^^^^^^^^^^^^^^^^^^^^^
TypeError: ReservationService.get_reservations_by_user_id() takes 1 positional argument but 2 were given
