2023-06-11 23:42:27,801 ERROR: Exception on /api/reservations/1 [GET] [in C:\Users\Glutt\miniconda3\envs\reserve\Lib\site-packages\flask\app.py:1744]
Traceback (most recent call last):
  File "C:\Users\Glutt\miniconda3\envs\reserve\Lib\site-packages\flask\app.py", line 2528, in wsgi_app
    response = self.full_dispatch_request()
               ^^^^^^^^^^^^^^^^^^^^^^^^^^^^
  File "C:\Users\Glutt\miniconda3\envs\reserve\Lib\site-packages\flask\app.py", line 1825, in full_dispatch_request
    rv = self.handle_user_exception(e)
         ^^^^^^^^^^^^^^^^^^^^^^^^^^^^^
  File "C:\Users\Glutt\miniconda3\envs\reserve\Lib\site-packages\flask_cors\extension.py", line 165, in wrapped_function
    return cors_after_request(app.make_response(f(*args, **kwargs)))
                                                ^^^^^^^^^^^^^^^^^^
  File "C:\Users\Glutt\miniconda3\envs\reserve\Lib\site-packages\flask\app.py", line 1823, in full_dispatch_request
    rv = self.dispatch_request()
         ^^^^^^^^^^^^^^^^^^^^^^^
  File "C:\Users\Glutt\miniconda3\envs\reserve\Lib\site-packages\flask\app.py", line 1799, in dispatch_request
    return self.ensure_sync(self.view_functions[rule.endpoint])(**view_args)
           ^^^^^^^^^^^^^^^^^^^^^^^^^^^^^^^^^^^^^^^^^^^^^^^^^^^^^^^^^^^^^^^^^
  File "C:\Users\Glutt\reservation_system\backend\app\routes.py", line 603, in get_reservation_user_id
    reservation = ReservationService.get_reservations_by_user_id(user_id)
           ^^^^^^^^^^^^^^^^^^^^
  File "C:\Users\Glutt\miniconda3\envs\reserve\Lib\site-packages\flask\json\__init__.py", line 342, in jsonify
    return current_app.json.response(*args, **kwargs)
           ^^^^^^^^^^^^^^^^^^^^^^^^^^^^^^^^^^^^^^^^^^
  File "C:\Users\Glutt\miniconda3\envs\reserve\Lib\site-packages\flask\json\provider.py", line 309, in response
    f"{self.dumps(obj, **dump_args)}\n", mimetype=mimetype
       ^^^^^^^^^^^^^^^^^^^^^^^^^^^^
  File "C:\Users\Glutt\miniconda3\envs\reserve\Lib\site-packages\flask\json\provider.py", line 230, in dumps
    return json.dumps(obj, **kwargs)
           ^^^^^^^^^^^^^^^^^^^^^^^^^
  File "C:\Users\Glutt\miniconda3\envs\reserve\Lib\json\__init__.py", line 238, in dumps
    **kw).encode(obj)
          ^^^^^^^^^^^
  File "C:\Users\Glutt\miniconda3\envs\reserve\Lib\json\encoder.py", line 200, in encode
    chunks = self.iterencode(o, _one_shot=True)
             ^^^^^^^^^^^^^^^^^^^^^^^^^^^^^^^^^^
  File "C:\Users\Glutt\miniconda3\envs\reserve\Lib\json\encoder.py", line 258, in iterencode
    return _iterencode(o, 0)
           ^^^^^^^^^^^^^^^^^
  File "C:\Users\Glutt\miniconda3\envs\reserve\Lib\site-packages\flask\json\provider.py", line 122, in _default
    raise TypeError(f"Object of type {type(o).__name__} is not JSON serializable")
TypeError: Object of type Reservation is not JSON serializable
2023-06-11 23:42:29,720 ERROR: Exception on /api/reservations/1 [GET] [in C:\Users\Glutt\miniconda3\envs\reserve\Lib\site-packages\flask\app.py:1744]
Traceback (most recent call last):
  File "C:\Users\Glutt\miniconda3\envs\reserve\Lib\site-packages\flask\app.py", line 2528, in wsgi_app
    response = self.full_dispatch_request()
               ^^^^^^^^^^^^^^^^^^^^^^^^^^^^
  File "C:\Users\Glutt\miniconda3\envs\reserve\Lib\site-packages\flask\app.py", line 1825, in full_dispatch_request
    rv = self.handle_user_exception(e)
         ^^^^^^^^^^^^^^^^^^^^^^^^^^^^^
  File "C:\Users\Glutt\miniconda3\envs\reserve\Lib\site-packages\flask_cors\extension.py", line 165, in wrapped_function
    return cors_after_request(app.make_response(f(*args, **kwargs)))
                                                ^^^^^^^^^^^^^^^^^^
  File "C:\Users\Glutt\miniconda3\envs\reserve\Lib\site-packages\flask\app.py", line 1823, in full_dispatch_request
    rv = self.dispatch_request()
         ^^^^^^^^^^^^^^^^^^^^^^^
  File "C:\Users\Glutt\miniconda3\envs\reserve\Lib\site-packages\flask\app.py", line 1799, in dispatch_request
    return self.ensure_sync(self.view_functions[rule.endpoint])(**view_args)
           ^^^^^^^^^^^^^^^^^^^^^^^^^^^^^^^^^^^^^^^^^^^^^^^^^^^^^^^^^^^^^^^^^
  File "C:\Users\Glutt\reservation_system\backend\app\routes.py", line 603, in get_reservation_user_id
    reservation = ReservationService.get_reservations_by_user_id(user_id)
           ^^^^^^^^^^^^^^^^^^^^
  File "C:\Users\Glutt\miniconda3\envs\reserve\Lib\site-packages\flask\json\__init__.py", line 342, in jsonify
    return current_app.json.response(*args, **kwargs)
           ^^^^^^^^^^^^^^^^^^^^^^^^^^^^^^^^^^^^^^^^^^
  File "C:\Users\Glutt\miniconda3\envs\reserve\Lib\site-packages\flask\json\provider.py", line 309, in response
    f"{self.dumps(obj, **dump_args)}\n", mimetype=mimetype
       ^^^^^^^^^^^^^^^^^^^^^^^^^^^^
  File "C:\Users\Glutt\miniconda3\envs\reserve\Lib\site-packages\flask\json\provider.py", line 230, in dumps
    return json.dumps(obj, **kwargs)
           ^^^^^^^^^^^^^^^^^^^^^^^^^
  File "C:\Users\Glutt\miniconda3\envs\reserve\Lib\json\__init__.py", line 238, in dumps
    **kw).encode(obj)
          ^^^^^^^^^^^
  File "C:\Users\Glutt\miniconda3\envs\reserve\Lib\json\encoder.py", line 200, in encode
    chunks = self.iterencode(o, _one_shot=True)
             ^^^^^^^^^^^^^^^^^^^^^^^^^^^^^^^^^^
  File "C:\Users\Glutt\miniconda3\envs\reserve\Lib\json\encoder.py", line 258, in iterencode
    return _iterencode(o, 0)
           ^^^^^^^^^^^^^^^^^
  File "C:\Users\Glutt\miniconda3\envs\reserve\Lib\site-packages\flask\json\provider.py", line 122, in _default
    raise TypeError(f"Object of type {type(o).__name__} is not JSON serializable")
TypeError: Object of type Reservation is not JSON serializable
2023-06-11 23:42:36,943 INFO: MyApp startup [in C:\Users\Glutt\reservation_system\backend\app\__init__.py:27]
2023-06-11 23:42:41,441 ERROR: Exception on /api/reservations/1 [GET] [in C:\Users\Glutt\miniconda3\envs\reserve\Lib\site-packages\flask\app.py:1744]
Traceback (most recent call last):
  File "C:\Users\Glutt\miniconda3\envs\reserve\Lib\site-packages\flask\app.py", line 2528, in wsgi_app
    response = self.full_dispatch_request()
               ^^^^^^^^^^^^^^^^^^^^^^^^^^^^
  File "C:\Users\Glutt\miniconda3\envs\reserve\Lib\site-packages\flask\app.py", line 1825, in full_dispatch_request
    rv = self.handle_user_exception(e)
         ^^^^^^^^^^^^^^^^^^^^^^^^^^^^^
  File "C:\Users\Glutt\miniconda3\envs\reserve\Lib\site-packages\flask_cors\extension.py", line 165, in wrapped_function
    return cors_after_request(app.make_response(f(*args, **kwargs)))
                                                ^^^^^^^^^^^^^^^^^^
  File "C:\Users\Glutt\miniconda3\envs\reserve\Lib\site-packages\flask\app.py", line 1823, in full_dispatch_request
    rv = self.dispatch_request()
         ^^^^^^^^^^^^^^^^^^^^^^^
  File "C:\Users\Glutt\miniconda3\envs\reserve\Lib\site-packages\flask\app.py", line 1799, in dispatch_request
    return self.ensure_sync(self.view_functions[rule.endpoint])(**view_args)
           ^^^^^^^^^^^^^^^^^^^^^^^^^^^^^^^^^^^^^^^^^^^^^^^^^^^^^^^^^^^^^^^^^
  File "C:\Users\Glutt\reservation_system\backend\app\routes.py", line 604, in get_reservation_user_id
    return jsonify(reservation.to_dict()),200
                   ^^^^^^^^^^^^^^^^^^^
AttributeError: 'list' object has no attribute 'to_dict'
2023-06-11 23:42:41,704 ERROR: Exception on /api/reservations/1 [GET] [in C:\Users\Glutt\miniconda3\envs\reserve\Lib\site-packages\flask\app.py:1744]
Traceback (most recent call last):
  File "C:\Users\Glutt\miniconda3\envs\reserve\Lib\site-packages\flask\app.py", line 2528, in wsgi_app
    response = self.full_dispatch_request()
               ^^^^^^^^^^^^^^^^^^^^^^^^^^^^
  File "C:\Users\Glutt\miniconda3\envs\reserve\Lib\site-packages\flask\app.py", line 1825, in full_dispatch_request
    rv = self.handle_user_exception(e)
         ^^^^^^^^^^^^^^^^^^^^^^^^^^^^^
  File "C:\Users\Glutt\miniconda3\envs\reserve\Lib\site-packages\flask_cors\extension.py", line 165, in wrapped_function
    return cors_after_request(app.make_response(f(*args, **kwargs)))
                                                ^^^^^^^^^^^^^^^^^^
  File "C:\Users\Glutt\miniconda3\envs\reserve\Lib\site-packages\flask\app.py", line 1823, in full_dispatch_request
    rv = self.dispatch_request()
         ^^^^^^^^^^^^^^^^^^^^^^^
  File "C:\Users\Glutt\miniconda3\envs\reserve\Lib\site-packages\flask\app.py", line 1799, in dispatch_request
    return self.ensure_sync(self.view_functions[rule.endpoint])(**view_args)
           ^^^^^^^^^^^^^^^^^^^^^^^^^^^^^^^^^^^^^^^^^^^^^^^^^^^^^^^^^^^^^^^^^
  File "C:\Users\Glutt\reservation_system\backend\app\routes.py", line 604, in get_reservation_user_id
    return jsonify(reservation.to_dict()),200
                   ^^^^^^^^^^^^^^^^^^^
AttributeError: 'list' object has no attribute 'to_dict'
2023-06-11 23:46:41,971 INFO: MyApp startup [in C:\Users\Glutt\reservation_system\backend\app\__init__.py:27]
