2023-06-11 23:47:09,272 ERROR: Exception on /api/reservations/1 [GET] [in C:\Users\Glutt\miniconda3\envs\reserve\Lib\site-packages\flask\app.py:1744]
Traceback (most recent call last):
  File "C:\Users\Glutt\miniconda3\envs\reserve\Lib\site-packages\flask\app.py", line 2528, in wsgi_app
    response = self.full_dispatch_request()
               ^^^^^^^^^^^^^^^^^^^^^^^^^^^^
  File "C:\Users\Glutt\miniconda3\envs\reserve\Lib\site-packages\flask\app.py", line 1825, in full_dispatch_request
    rv = self.handle_user_exception(e)
         ^^^^^^^^^^^^^^^^^^^^^^^^^^^^^
  File "C:\Users\Glutt\miniconda3\envs\reserve\Lib\site-packages\flask_cors\extension.py", line 165, in wrapped_function
    return cors_after_request(app.make_response(f(*args, **kwargs)))
                                                ^^^^^^^^^^^^^^^^^^
  File "C:\Users\Glutt\miniconda3\envs\reserve\Lib\site-packages\flask\app.py", line 1823, in full_dispatch_request
    rv = self.dispatch_request()
         ^^^^^^^^^^^^^^^^^^^^^^^
  File "C:\Users\Glutt\miniconda3\envs\reserve\Lib\site-packages\flask\app.py", line 1799, in dispatch_request
    return self.ensure_sync(self.view_functions[rule.endpoint])(**view_args)
           ^^^^^^^^^^^^^^^^^^^^^^^^^^^^^^^^^^^^^^^^^^^^^^^^^^^^^^^^^^^^^^^^^
  File "C:\Users\Glutt\reservation_system\backend\app\routes.py", line 606, in get_reservation_user_id
    return jsonify(reservation.to_dict()),200
                   ^^^^^^^^^^^^^^^^^^^
AttributeError: 'list' object has no attribute 'to_dict'
2023-06-11 23:47:09,516 ERROR: Exception on /api/reservations/1 [GET] [in C:\Users\Glutt\miniconda3\envs\reserve\Lib\site-packages\flask\app.py:1744]
Traceback (most recent call last):
  File "C:\Users\Glutt\miniconda3\envs\reserve\Lib\site-packages\flask\app.py", line 2528, in wsgi_app
    response = self.full_dispatch_request()
               ^^^^^^^^^^^^^^^^^^^^^^^^^^^^
  File "C:\Users\Glutt\miniconda3\envs\reserve\Lib\site-packages\flask\app.py", line 1825, in full_dispatch_request
    rv = self.handle_user_exception(e)
         ^^^^^^^^^^^^^^^^^^^^^^^^^^^^^
  File "C:\Users\Glutt\miniconda3\envs\reserve\Lib\site-packages\flask_cors\extension.py", line 165, in wrapped_function
    return cors_after_request(app.make_response(f(*args, **kwargs)))
                                                ^^^^^^^^^^^^^^^^^^
  File "C:\Users\Glutt\miniconda3\envs\reserve\Lib\site-packages\flask\app.py", line 1823, in full_dispatch_request
    rv = self.dispatch_request()
         ^^^^^^^^^^^^^^^^^^^^^^^
  File "C:\Users\Glutt\miniconda3\envs\reserve\Lib\site-packages\flask\app.py", line 1799, in dispatch_request
    return self.ensure_sync(self.view_functions[rule.endpoint])(**view_args)
           ^^^^^^^^^^^^^^^^^^^^^^^^^^^^^^^^^^^^^^^^^^^^^^^^^^^^^^^^^^^^^^^^^
  File "C:\Users\Glutt\reservation_system\backend\app\routes.py", line 606, in get_reservation_user_id
    return jsonify(reservation.to_dict()),200
                   ^^^^^^^^^^^^^^^^^^^
AttributeError: 'list' object has no attribute 'to_dict'
2023-06-11 23:48:34,669 ERROR: Exception on /api/reservations/1 [GET] [in C:\Users\Glutt\miniconda3\envs\reserve\Lib\site-packages\flask\app.py:1744]
Traceback (most recent call last):
  File "C:\Users\Glutt\miniconda3\envs\reserve\Lib\site-packages\flask\app.py", line 2528, in wsgi_app
    response = self.full_dispatch_request()
               ^^^^^^^^^^^^^^^^^^^^^^^^^^^^
  File "C:\Users\Glutt\miniconda3\envs\reserve\Lib\site-packages\flask\app.py", line 1825, in full_dispatch_request
    rv = self.handle_user_exception(e)
         ^^^^^^^^^^^^^^^^^^^^^^^^^^^^^
  File "C:\Users\Glutt\miniconda3\envs\reserve\Lib\site-packages\flask_cors\extension.py", line 165, in wrapped_function
    return cors_after_request(app.make_response(f(*args, **kwargs)))
                                                ^^^^^^^^^^^^^^^^^^
  File "C:\Users\Glutt\miniconda3\envs\reserve\Lib\site-packages\flask\app.py", line 1823, in full_dispatch_request
    rv = self.dispatch_request()
         ^^^^^^^^^^^^^^^^^^^^^^^
  File "C:\Users\Glutt\miniconda3\envs\reserve\Lib\site-packages\flask\app.py", line 1799, in dispatch_request
    return self.ensure_sync(self.view_functions[rule.endpoint])(**view_args)
           ^^^^^^^^^^^^^^^^^^^^^^^^^^^^^^^^^^^^^^^^^^^^^^^^^^^^^^^^^^^^^^^^^
  File "C:\Users\Glutt\reservation_system\backend\app\routes.py", line 606, in get_reservation_user_id
    return jsonify(reservation.to_dict()),200
                   ^^^^^^^^^^^^^^^^^^^
AttributeError: 'list' object has no attribute 'to_dict'
2023-06-11 23:48:34,930 ERROR: Exception on /api/reservations/1 [GET] [in C:\Users\Glutt\miniconda3\envs\reserve\Lib\site-packages\flask\app.py:1744]
Traceback (most recent call last):
  File "C:\Users\Glutt\miniconda3\envs\reserve\Lib\site-packages\flask\app.py", line 2528, in wsgi_app
    response = self.full_dispatch_request()
               ^^^^^^^^^^^^^^^^^^^^^^^^^^^^
  File "C:\Users\Glutt\miniconda3\envs\reserve\Lib\site-packages\flask\app.py", line 1825, in full_dispatch_request
    rv = self.handle_user_exception(e)
         ^^^^^^^^^^^^^^^^^^^^^^^^^^^^^
  File "C:\Users\Glutt\miniconda3\envs\reserve\Lib\site-packages\flask_cors\extension.py", line 165, in wrapped_function
    return cors_after_request(app.make_response(f(*args, **kwargs)))
                                                ^^^^^^^^^^^^^^^^^^
  File "C:\Users\Glutt\miniconda3\envs\reserve\Lib\site-packages\flask\app.py", line 1823, in full_dispatch_request
    rv = self.dispatch_request()
         ^^^^^^^^^^^^^^^^^^^^^^^
  File "C:\Users\Glutt\miniconda3\envs\reserve\Lib\site-packages\flask\app.py", line 1799, in dispatch_request
    return self.ensure_sync(self.view_functions[rule.endpoint])(**view_args)
           ^^^^^^^^^^^^^^^^^^^^^^^^^^^^^^^^^^^^^^^^^^^^^^^^^^^^^^^^^^^^^^^^^
  File "C:\Users\Glutt\reservation_system\backend\app\routes.py", line 606, in get_reservation_user_id
    return jsonify(reservation.to_dict()),200
                   ^^^^^^^^^^^^^^^^^^^
AttributeError: 'list' object has no attribute 'to_dict'
2023-06-11 23:49:05,169 INFO: MyApp startup [in C:\Users\Glutt\reservation_system\backend\app\__init__.py:27]
2023-06-11 23:49:09,035 ERROR: Exception on /api/reservations/1 [GET] [in C:\Users\Glutt\miniconda3\envs\reserve\Lib\site-packages\flask\app.py:1744]
Traceback (most recent call last):
  File "C:\Users\Glutt\miniconda3\envs\reserve\Lib\site-packages\flask\app.py", line 2528, in wsgi_app
    response = self.full_dispatch_request()
               ^^^^^^^^^^^^^^^^^^^^^^^^^^^^
  File "C:\Users\Glutt\miniconda3\envs\reserve\Lib\site-packages\flask\app.py", line 1825, in full_dispatch_request
    rv = self.handle_user_exception(e)
         ^^^^^^^^^^^^^^^^^^^^^^^^^^^^^
  File "C:\Users\Glutt\miniconda3\envs\reserve\Lib\site-packages\flask_cors\extension.py", line 165, in wrapped_function
    return cors_after_request(app.make_response(f(*args, **kwargs)))
                                                ^^^^^^^^^^^^^^^^^^
  File "C:\Users\Glutt\miniconda3\envs\reserve\Lib\site-packages\flask\app.py", line 1823, in full_dispatch_request
    rv = self.dispatch_request()
         ^^^^^^^^^^^^^^^^^^^^^^^
  File "C:\Users\Glutt\miniconda3\envs\reserve\Lib\site-packages\flask\app.py", line 1799, in dispatch_request
    return self.ensure_sync(self.view_functions[rule.endpoint])(**view_args)
           ^^^^^^^^^^^^^^^^^^^^^^^^^^^^^^^^^^^^^^^^^^^^^^^^^^^^^^^^^^^^^^^^^
  File "C:\Users\Glutt\reservation_system\backend\app\routes.py", line 606, in get_reservation_user_id
    return jsonify(reservation.to_dict()),200
                   ^^^^^^^^^^^^^^^^^^^
AttributeError: 'list' object has no attribute 'to_dict'
2023-06-11 23:49:09,287 ERROR: Exception on /api/reservations/1 [GET] [in C:\Users\Glutt\miniconda3\envs\reserve\Lib\site-packages\flask\app.py:1744]
Traceback (most recent call last):
  File "C:\Users\Glutt\miniconda3\envs\reserve\Lib\site-packages\flask\app.py", line 2528, in wsgi_app
    response = self.full_dispatch_request()
               ^^^^^^^^^^^^^^^^^^^^^^^^^^^^
  File "C:\Users\Glutt\miniconda3\envs\reserve\Lib\site-packages\flask\app.py", line 1825, in full_dispatch_request
    rv = self.handle_user_exception(e)
         ^^^^^^^^^^^^^^^^^^^^^^^^^^^^^
  File "C:\Users\Glutt\miniconda3\envs\reserve\Lib\site-packages\flask_cors\extension.py", line 165, in wrapped_function
    return cors_after_request(app.make_response(f(*args, **kwargs)))
                                                ^^^^^^^^^^^^^^^^^^
  File "C:\Users\Glutt\miniconda3\envs\reserve\Lib\site-packages\flask\app.py", line 1823, in full_dispatch_request
    rv = self.dispatch_request()
         ^^^^^^^^^^^^^^^^^^^^^^^
  File "C:\Users\Glutt\miniconda3\envs\reserve\Lib\site-packages\flask\app.py", line 1799, in dispatch_request
    return self.ensure_sync(self.view_functions[rule.endpoint])(**view_args)
           ^^^^^^^^^^^^^^^^^^^^^^^^^^^^^^^^^^^^^^^^^^^^^^^^^^^^^^^^^^^^^^^^^
  File "C:\Users\Glutt\reservation_system\backend\app\routes.py", line 606, in get_reservation_user_id
    return jsonify(reservation.to_dict()),200
                   ^^^^^^^^^^^^^^^^^^^
AttributeError: 'list' object has no attribute 'to_dict'
